<?xml version="1.0" ?>
<!-- =================================================================================== -->
<!-- |    This document was autogenerated by xacro from exo_model.xacro.urdf           | -->
<!-- |    EDITING THIS FILE BY HAND IS NOT RECOMMENDED                                 | -->
<!-- =================================================================================== -->
<robot name="exo_model">
  <!-- materials -->
  <material name="black">
    <color rgba="0.0 0.0 0.0 1.0"/>
  </material>
  <material name="grey">
    <color rgba="0.7 0.7 0.7 1.0"/>
  </material>
  <link name="dummy_link">
    <collision>
      <geometry>
        <box size="0.2 1.0 0.2"/>
      </geometry>
    </collision>
    <inertial>
      <origin xyz="0 0 0"/>
      <mass value="5.0"/>
      <inertia ixx="0.5" ixy="0" ixz="0" iyy="0.5" iyz="0" izz="0.5"/>
    </inertial>
  </link>
  <link name="base_link">
    <visual>
      <geometry>
        <box size="0.2 1.0 0.2"/>
      </geometry>
    </visual>
    <collision>
      <geometry>
        <box size="0.2 1.0 0.2"/>
      </geometry>
    </collision>
  </link>
  <joint name="base_fixedpoint" type="fixed">
    <parent link="base_link"/>
    <child link="dummy_link"/>
  </joint>
  <link name="left_hip_motor_link">
    <visual>
      <geometry>
        <cylinder length="0.15" radius="0.2"/>
      </geometry>
      <origin rpy="1.57 0 0" xyz="0 0 0"/>
      <!-- 90 degree is 1.57 rad -->
      <material name="black"/>
    </visual>
    <collision>
      <geometry>
        <cylinder length="0.15" radius="0.2"/>
      </geometry>
      <origin rpy="1.57 0 0" xyz="0 0 0"/>
    </collision>
    <!-- approximated inertia -->
    <inertial>
      <origin xyz="0 0 0"/>
      <mass value="0.3"/>
      <inertia ixx="0.002" ixy="0" ixz="0" iyy="0.002" iyz="0" izz="0.002"/>
    </inertial>
  </link>
  <link name="left_thigh_stand_link">
    <visual>
      <geometry>
        <box size="0.2 0.2 0.5"/>
      </geometry>
      <origin xyz="0 0 -0.25"/>
      <material name="grey"/>
    </visual>
    <collision>
      <geometry>
        <box size="0.2 0.2 0.5"/>
      </geometry>
      <origin xyz="0 0 -0.25"/>
    </collision>
    <inertial>
      <origin xyz="0 0 -0.25"/>
      <mass value="1.0"/>
      <inertia ixx="0.034166666666666665" ixy="0" ixz="0" iyy="0.02416666666666667" iyz="0" izz="0.01666666666666667"/>
    </inertial>
  </link>
  <link name="left_knee_motor_link">
    <visual>
      <geometry>
        <cylinder length="0.15" radius="0.2"/>
      </geometry>
      <origin rpy="1.57 0 0" xyz="0 0 0"/>
      <!-- 90 degree is 1.57 rad -->
      <material name="black"/>
    </visual>
    <collision>
      <geometry>
        <cylinder length="0.15" radius="0.2"/>
      </geometry>
      <origin rpy="1.57 0 0" xyz="0 0 0"/>
    </collision>
    <!-- approximated inertia -->
    <inertial>
      <origin xyz="0 0 0"/>
      <mass value="0.3"/>
      <inertia ixx="0.002" ixy="0" ixz="0" iyy="0.002" iyz="0" izz="0.002"/>
    </inertial>
  </link>
  <link name="left_shin_stand_link">
    <visual>
      <geometry>
        <box size="0.2 0.2 0.7"/>
      </geometry>
      <origin xyz="0 0 -0.35"/>
      <material name="grey"/>
    </visual>
    <collision>
      <geometry>
        <box size="0.2 0.2 0.7"/>
      </geometry>
      <origin xyz="0 0 -0.35"/>
    </collision>
    <inertial>
      <origin xyz="0 0 -0.35"/>
      <mass value="1.2"/>
      <inertia ixx="0.06499999999999999" ixy="0" ixz="0" iyy="0.052999999999999985" iyz="0" izz="0.020000000000000004"/>
    </inertial>
  </link>
  <!-- joints setting -->
  <joint name="left_hip_joint" type="revolute">
    <parent link="base_link"/>
    <child link="left_hip_motor_link"/>
    <origin xyz="0 -0.55 0"/>
    <axis xyz="0 1 0"/>
    <limit effort="60" lower="-1.5" upper="1.5" velocity="3.0"/>
  </joint>
  <joint name="link_left_hip_motor_and_thigh" type="fixed">
    <parent link="left_hip_motor_link"/>
    <child link="left_thigh_stand_link"/>
    <origin xyz="0 0 -0.2"/>
  </joint>
  <joint name="link_left_thigh_and_knee_motor" type="fixed">
    <parent link="left_thigh_stand_link"/>
    <child link="left_knee_motor_link"/>
    <origin xyz="0 0 -0.7"/>
  </joint>
  <joint name="left_knee_joint" type="revolute">
    <parent link="left_knee_motor_link"/>
    <child link="left_shin_stand_link"/>
    <origin xyz="0 0 0"/>
    <axis xyz="0 1 0"/>
    <limit effort="40" lower="0" upper="1.5" velocity="3.0"/>
  </joint>
  <link name="right_hip_motor_link">
    <visual>
      <geometry>
        <cylinder length="0.15" radius="0.2"/>
      </geometry>
      <origin rpy="1.57 0 0" xyz="0 0 0"/>
      <!-- 90 degree is 1.57 rad -->
      <material name="black"/>
    </visual>
    <collision>
      <geometry>
        <cylinder length="0.15" radius="0.2"/>
      </geometry>
      <origin rpy="1.57 0 0" xyz="0 0 0"/>
    </collision>
    <!-- approximated inertia -->
    <inertial>
      <origin xyz="0 0 0"/>
      <mass value="0.3"/>
      <inertia ixx="0.002" ixy="0" ixz="0" iyy="0.002" iyz="0" izz="0.002"/>
    </inertial>
  </link>
  <link name="right_thigh_stand_link">
    <visual>
      <geometry>
        <box size="0.2 0.2 0.5"/>
      </geometry>
      <origin xyz="0 0 -0.25"/>
      <material name="grey"/>
    </visual>
    <collision>
      <geometry>
        <box size="0.2 0.2 0.5"/>
      </geometry>
      <origin xyz="0 0 -0.25"/>
    </collision>
    <inertial>
      <origin xyz="0 0 -0.25"/>
      <mass value="1.0"/>
      <inertia ixx="0.034166666666666665" ixy="0" ixz="0" iyy="0.02416666666666667" iyz="0" izz="0.01666666666666667"/>
    </inertial>
  </link>
  <link name="right_knee_motor_link">
    <visual>
      <geometry>
        <cylinder length="0.15" radius="0.2"/>
      </geometry>
      <origin rpy="1.57 0 0" xyz="0 0 0"/>
      <!-- 90 degree is 1.57 rad -->
      <material name="black"/>
    </visual>
    <collision>
      <geometry>
        <cylinder length="0.15" radius="0.2"/>
      </geometry>
      <origin rpy="1.57 0 0" xyz="0 0 0"/>
    </collision>
    <!-- approximated inertia -->
    <inertial>
      <origin xyz="0 0 0"/>
      <mass value="0.3"/>
      <inertia ixx="0.002" ixy="0" ixz="0" iyy="0.002" iyz="0" izz="0.002"/>
    </inertial>
  </link>
  <link name="right_shin_stand_link">
    <visual>
      <geometry>
        <box size="0.2 0.2 0.7"/>
      </geometry>
      <origin xyz="0 0 -0.35"/>
      <material name="grey"/>
    </visual>
    <collision>
      <geometry>
        <box size="0.2 0.2 0.7"/>
      </geometry>
      <origin xyz="0 0 -0.35"/>
    </collision>
    <inertial>
      <origin xyz="0 0 -0.35"/>
      <mass value="1.2"/>
      <inertia ixx="0.06499999999999999" ixy="0" ixz="0" iyy="0.052999999999999985" iyz="0" izz="0.020000000000000004"/>
    </inertial>
  </link>
  <!-- joints setting -->
  <joint name="right_hip_joint" type="revolute">
    <parent link="base_link"/>
    <child link="right_hip_motor_link"/>
    <origin xyz="0 0.55 0"/>
    <axis xyz="0 1 0"/>
    <limit effort="60" lower="-1.5" upper="1.5" velocity="3.0"/>
  </joint>
  <joint name="link_right_hip_motor_and_thigh" type="fixed">
    <parent link="right_hip_motor_link"/>
    <child link="right_thigh_stand_link"/>
    <origin xyz="0 0 -0.2"/>
  </joint>
  <joint name="link_right_thigh_and_knee_motor" type="fixed">
    <parent link="right_thigh_stand_link"/>
    <child link="right_knee_motor_link"/>
    <origin xyz="0 0 -0.7"/>
  </joint>
  <joint name="right_knee_joint" type="revolute">
    <parent link="right_knee_motor_link"/>
    <child link="right_shin_stand_link"/>
    <origin xyz="0 0 0"/>
    <axis xyz="0 1 0"/>
    <limit effort="40" lower="0" upper="1.5" velocity="3.0"/>
  </joint>
  <!-- import other xacro files or plugins -->
</robot>
